#VRML_SIM R2022a utf8
WorldInfo {
}
Viewpoint {
  orientation 0.002953524236892541 -0.9999466572126655 -0.009897445316762557 5.7031560726232495
  position -0.46268888033396827 -0.0525373579574312 0.39911465816076386
}
TexturedBackground {
}
TexturedBackgroundLight {
}
RectangleArena {
  rotation 0 1 0 0
}
Robot {
  translation 0 0 0.017
  children [
    Solid {
      translation 0 -0.006 0
      children [
        Transform {
          rotation 0 1 0 0
          children [
            Shape {
              appearance DEF plastic_appearance PBRAppearance {
                baseColor 0.3 0.3 0.3
                roughness 1
                metalness 0
              }
              geometry Mesh {
                url [
                  "meshes/eeezybotarm/EBA_01.00.010_basement.STL"
                ]
              }
            }
          ]
        }
        HingeJoint {
          jointParameters HingeJointParameters {
            axis 0 0 1
            anchor 0 0.006 0
          }
          device [
            DEF motor_1 RotationalMotor {
              name "motor_1"
            }
          ]
          endPoint DEF motor_1_arm Solid {
            translation 0 0.006 0.02
            children [
              Group {
                children [
                  Shape {
                    appearance USE plastic_appearance
                    geometry Mesh {
                      url [
                        "meshes/eeezybotarm/EBA_01.00.011_round_plate.STL"
                      ]
                    }
                  }
                  Transform {
                    translation -0.001 -0.0005 0
                    rotation 0 0 1 3.1415
                    children [
                      Shape {
                        appearance USE plastic_appearance
                        geometry Mesh {
                          url [
                            "meshes/eeezybotarm/EBA_01.00.001.STL"
                          ]
                        }
                      }
                    ]
                  }
                  Transform {
                    translation 0.0175 0 0.032
                    rotation -0.5773517358546668 0.5773497358555818 0.5773493358557649 2.0939375
                    children [
                      DEF servo_shape Shape {
                        appearance USE plastic_appearance
                        geometry DEF servo_mesh Mesh {
                          url [
                            "meshes/eeezybotarm/SG90.stl"
                          ]
                        }
                      }
                    ]
                  }
                  Transform {
                    translation -0.0145 0 0.032
                    rotation 0.5773501794597087 0.5773501794597087 -0.5773504486494182 2.09
                    children [
                      USE servo_shape
                    ]
                  }
                ]
              }
              HingeJoint {
                jointParameters HingeJointParameters {
                  position 1
                  axis -1 0 0
                  anchor 0 0 0.0325
                }
                device [
                  DEF motor_2 RotationalMotor {
                    name "motor_2"
                  }
                ]
                endPoint DEF motor_2_arm Solid {
                  translation -0.001 0 0.0325
                  rotation -9.83320791262823e-11 -0.479425538604203 -0.8775825618903728 3.141592653229803
                  children [
                    DEF horizontal_pivot HingeJoint {
                      jointParameters HingeJointParameters {
                        position 1.55
                        axis -1 0 0
                        anchor 0 0.08 -0.0025
                        minStop -3
                        maxStop 3
                      }
                      endPoint DEF horizontal_arm Solid {
                        translation 0.001 0.08 -0.0025
                        rotation -1 0 0 1.55
                        children [
                          Shape {
                            appearance USE plastic_appearance
                            geometry Mesh {
                              url [
                                "meshes/eeezybotarm/EBA_01.00.005_horizontal_arm.STL"
                              ]
                            }
                          }
                          DEF horizontal_link HingeJoint {
                            jointParameters HingeJointParameters {
                              position 1.52
                              anchor 0 -0.035 0
                            }
                            endPoint DEF link_solid Solid {
                              translation -0.007 -0.035 0
                              rotation 0.7078666013883795 -0.017937966095469746 -0.7061183356996352 3.1020423905104675
                              children [
                                Shape {
                                  appearance USE plastic_appearance
                                  geometry Mesh {
                                    url [
                                      "meshes/eeezybotarm/EBA_01.00.003_link.STL"
                                    ]
                                  }
                                }
                                HingeJoint {
                                  jointParameters HingeJointParameters {
                                    axis 0 0 1
                                    anchor 0.08 0 0
                                  }
                                  endPoint SolidReference {
                                    solidName "motor_3_arm"
                                  }
                                }
                              ]
                              name "link_1"
                              boundingObject Transform {
                                translation 0.04 0 0
                                children [
                                  Box {
                                    size 0.04 0.01 0.01
                                  }
                                ]
                              }
                              physics Physics {
                              }
                            }
                          }
                        ]
                        name "horizontal_arm"
                        boundingObject Transform {
                          translation 0 0.022 0
                          children [
                            Box {
                              size 0.01 0.08 0.01
                            }
                          ]
                        }
                        physics Physics {
                        }
                      }
                    }
                    Shape {
                      appearance USE plastic_appearance
                      geometry Mesh {
                        url [
                          "meshes/eeezybotarm/EBA_01.00.004_forward_drive_arm.STL"
                        ]
                      }
                    }
                    DEF trangular_pivot HingeJoint {
                      jointParameters HingeJointParameters {
                        position -1.08
                        anchor 0 0.08 -0.0025
                        minStop -3
                        maxStop 3
                      }
                      endPoint DEF triangular_link_solid Solid {
                        translation 0.012000000000000028 0.08 -0.0025
                        rotation -1 0 0 0.9800000000000016
                        children [
                          DEF triangle_rear_link HingeJoint {
                            jointParameters HingeJointParameters {
                              position 0.9
                              anchor 0 -0.036 0.0175
                            }
                            endPoint Solid {
                              translation 0 -0.036 0.0175
                              rotation 1 0 0 0.9000000000000001
                              children [
                                DEF link_xfor Transform {
                                  translation 0.005 0 0
                                  rotation -0.5773502691896258 0.5773502691896258 -0.5773502691896258 2.09
                                  children [
                                    DEF link_shape Shape {
                                      appearance USE plastic_appearance
                                      geometry Mesh {
                                        url [
                                          "meshes/eeezybotarm/EBA_01.00.003_link.STL"
                                        ]
                                      }
                                    }
                                    HingeJoint {
                                      jointParameters HingeJointParameters {
                                        axis 0 0 1
                                        anchor 0.08 0 0
                                        minStop -3
                                        maxStop 3
                                      }
                                      endPoint SolidReference {
                                        solidName "turret"
                                      }
                                    }
                                  ]
                                }
                              ]
                              name "rear_triangle_link"
                              boundingObject Transform {
                                translation 0.005 -0.04 0
                                children [
                                  Box {
                                    size 0.01 0.04 0.01
                                  }
                                ]
                              }
                              physics Physics {
                              }
                            }
                          }
                          Shape {
                            appearance USE plastic_appearance
                            geometry Mesh {
                              url [
                                "meshes/eeezybotarm/EBA_01.00.006_triangular_link.STL"
                              ]
                            }
                          }
                          HingeJoint {
                            jointParameters HingeJointParameters {
                              position -0.55
                              anchor -0.005 0.0102 0.0175
                            }
                            endPoint DEF front_triangle_link_solid Solid {
                              translation 7.806255641895632e-18 0.0102 0.0175
                              rotation -1 0 0 0.5499999999999998
                              children [
                                Transform {
                                  rotation 0.5773502691896258 0.5773502691896258 0.5773502691896258 2.09
                                  children [
                                    USE link_shape
                                  ]
                                }
                                HingeJoint {
                                  jointParameters HingeJointParameters {
                                    position 0.5
                                    anchor 0 0.08 0
                                  }
                                  endPoint Solid {
                                    translation -0.0019999999999999966 0.08 0
                                    rotation 1 0 0 0.5000000000000004
                                    children [
                                      Shape {
                                        appearance USE plastic_appearance
                                        geometry Mesh {
                                          url [
                                            "meshes/eeezybotarm/EBA_01.00.012_R01_claw_support v2.stl"
                                          ]
                                        }
                                      }
                                      DEF link-claw HingeJoint {
                                        jointParameters HingeJointParameters {
                                          anchor 0 -0.01 -0.018
                                        }
                                        endPoint SolidReference {
                                          solidName "horizontal_arm"
                                        }
                                      }
                                    ]
                                    boundingObject Transform {
                                      translation -0.008 0.015 -0.03
                                      children [
                                        Box {
                                          size 0.02 0.03 0.005
                                        }
                                      ]
                                    }
                                    physics Physics {
                                    }
                                  }
                                }
                              ]
                              name "front_triangle_link_solid"
                              boundingObject Transform {
                                translation 0 0.04 0
                                children [
                                  Box {
                                    size 0.005 0.04 0.005
                                  }
                                ]
                              }
                              physics Physics {
                              }
                            }
                          }
                        ]
                        boundingObject Transform {
                          translation 0 -0.015 0.015
                          rotation 1 0 0 1.5708
                          children [
                            Capsule {
                              height 0.03
                              radius 0.002
                              subdivision 16
                            }
                          ]
                        }
                        physics Physics {
                        }
                      }
                    }
                  ]
                  name "vertical_arm"
                  boundingObject Transform {
                    translation 0 0.04 0
                    children [
                      Box {
                        size 0.02 0.04 0.02
                      }
                    ]
                  }
                  physics Physics {
                  }
                }
              }
              HingeJoint {
                jointParameters HingeJointParameters {
                  position 1
                  axis -1 0 0
                  anchor 0 0 0.0325
                }
                device [
                  DEF motor_3 RotationalMotor {
                    name "motor_3"
                  }
                ]
                endPoint DEF motor_3_arm Solid {
                  translation 0.015 0 0.0325
                  rotation -0.4323087228533422 0.791338715916305 -0.43231031081486554 1.802721602373887
                  children [
                    Shape {
                      appearance USE plastic_appearance
                      geometry Mesh {
                        url [
                          "meshes/eeezybotarm/EBA_01.00.002_vertical_drive_arm.STL"
                        ]
                      }
                    }
                  ]
                  name "motor_3_arm"
                  boundingObject Transform {
                    translation -0.0175 0 0
                    children [
                      Box {
                        size 0.035 0.01 0.01
                      }
                    ]
                  }
                  physics Physics {
                  }
                }
              }
            ]
            name "turret"
            boundingObject Transform {
              translation -0.001 0 0
              rotation 0 0 1 3.14159
              children [
                Mesh {
                  url [
                    "meshes/eeezybotarm/EBA_01.00.001.STL"
                  ]
                }
              ]
            }
            physics Physics {
            }
          }
        }
      ]
      name "basement"
    }
  ]
  name "eeezybotarm"
  boundingObject Cylinder {
    height 0.03
    radius 0.035
  }
  physics Physics {
  }
  controller "eeezybotarm_test"
}
